Workbook

Sheet Income Statement
A1: BASF — Income Statement (FY2021–FY2025)
A2: Revenue | B2: 78598 | C2: 87327 | D2: 68902 | E2: 61444 | F2: 59657
A3: Revenue Growth | B3: 0.3288 | C3: 0.1111 | D3: -0.211 | E3: -0.1082 | F3: -0.0291
A4: Cost of Revenue | B4: 59091 | C4: 66697 | D4: 52506 | E4: 46534 | F4: 45527
A5: Gross Profit | B5: 19507 | C5: 20630 | D5: 16396 | E5: 14910 | F5: 14130
A6: Selling, General & Admin | B6: 9902 | C6: 11201 | D6: 10379 | E6: 9025 | F6: 8883
A7: Research & Development | B7: 2216 | C7: 2298 | D7: 2130 | E7: 1969 | F7: 1995
A8: Other Operating Expenses | B8: -115 | C8: 275 | D8: 1046 | E8: 1432 | F8: 779
A9: Operating Expenses | B9: 12040 | C9: 13774 | D9: 13555 | E9: 12426 | F9: 11657
A10: Operating Income | B10: 7467 | C10: 6856 | D10: 2841 | E10: 2484 | F10: 2473
A11: Interest Expense | B11: -506 | C11: -631 | D11: -868 | E11: -929 | F11: -924
A12: Interest & Investment Income | B12: 257 | C12: 354 | D12: 453 | E12: 512 | F12: 406
A13: Earnings From Equity Investments | B13: 960 | C13: -4499 | D13: 78 | E13: 653 | F13: 1055
... A35: EPS Growth | B35: 0 | C35: 0 | D35: 0 | E35: 4.8 | F35: 0.2483

Sheet Balance Sheet
A1: BASF — Balance Sheet (FY2021–FY2025)
A2: Fiscal Year | B2: FY 2021 | C2: FY 2022 | D2: FY 2023 | E2: FY 2024 | F2: FY 2025
A3: Cash & Equivalents | B3: 2624 | C3: 2516 | D3: 2624 | E3: 2914 | F3: 2670
A4: Short-Term Investments | B4: 208 | C4: 232 | D4: 53 | E4: 67 | F4: 89
A5: Trading Asset Securities | B5: 1554 | C5: 1939 | D5: 1139 | E5: 0 | F5: 1327
A6: Cash & Short-Term Investments | B6: 4386 | C6: 4687 | D6: 3816 | E6: 2981 | F6: 4086
A7: Cash Growth | B7: -0.2858 | C7: 0.0686 | D7: -0.1858 | E7: -0.2188 | F7: 0.3707
A8: Accounts Receivable | B8: 11946 | C8: 12057 | D8: 10417 | E8: 10393 | F8: 8327
A9: Other Receivables | B9: 2187 | C9: 2485 | D9: 1761 | E9: 3996 | F9: 1623
A10: Receivables | B10: 14282 | C10: 14645 | D10: 12360 | E10: 14389 | F10: 10088
A11: Inventory | B11: 13868 | C11: 16028 | D11: 13876 | E11: 13681 | F11: 12168
A12: Prepaid Expenses | B12: 327 | C12: 285 | D12: 225 | E12: 0 | F12: 207
A13: Other Current Assets | B13: 2188 | C13: 1777 | D13: 1195 | E13: 181 | F13: 5135
A14: Total Current Assets | B14: 35051 | C14: 37422 | D14: 31472 | E14: 31232 | F14: 31684
... A22: Total Assets | B22: 87383 | C22: 84472 | D22: 77395 | E22: 80415 | F22: 76174
A24: Average Accounts Receivable | C24: =(B8+C8)/2 -> 12001.5 | D24: =(C8+D8)/2 -> 11237 | E24: =(D8+E8)/2 -> 10405 | F24: =(E8+F8)/2 -> 9360
A26: Liabilities
A27: Fiscal Year | B27: FY 2021 | C27: FY 2022 | D27: FY 2023 | E27: FY 2024 | F27: FY 2025
A28: Accounts Payable | B28: 7826 | C28: 8434 | D28: 6741 | E28: 6923 | F28: 5484
A29: Accrued Expenses | B29: 2374 | C29: 2054 | D29: 1414 | E29: 1579 | F29: 1671
A30: Short-Term Debt | B30: 248 | C30: 654 | D30: 0 | E30: 0 | F30: 0
A31: Current Portion of Long-Term Debt | B31: 3677 | C31: 3615 | D31: 2597 | E31: 3200 | F31: 3167
A32: Current Portion of Leases | B32: 334 | C32: 329 | D32: 350 | E32: 340 | F32: 342
A33: Current Income Taxes Payable | B33: 1161 | C33: 995 | D33: 442 | E33: 404 | F33: 213
A34: Current Unearned Revenue | B34: 1021 | C34: 1016 | D34: 853 | E34: 803 | F34: 709
A35: Other Current Liabilities | B35: 3440 | C35: 3343 | D35: 3474 | E35: 3790 | F35: 4825
A36: Total Current Liabilities | B36: 20081 | C36: 20440 | D36: 15871 | E36: 17039 | F36: 16411
A37: Long-Term Debt | B37: 13799 | C37: 15192 | D37: 17101 | E37: 19132 | F37: 18488
A38: Long-Term Leases | B38: 1078 | C38: 1159 | D38: 1299 | E38: 1323 | F38: 1212
A39: Long-Term Unearned Revenue | B39: 218 | C39: 192 | D39: 160 | E39: 217 | F39: 238
... A43: Total Liabilities | B43: 45302 | C43: 43549 | D43: 40750 | E43: 43532 | F43: 41837
A44: Total Debt | B44: =SUM(B30,B31,B37) -> 17724 | C44: =SUM(C30,C31,C37) -> 19461 | D44: =SUM(D30,D31,D37) -> 19698 | E44: =SUM(E30,E31,E37) -> 22332 | F44: =SUM(F30,F31,F37) -> 21655
A46: Shareholders' Equity
A47: Fiscal Year | B47: FY 2021 | C47: FY 2022 | D47: FY 2023 | E47: FY 2024 | F47: FY 2025
A48: Common Stock | B48: 1176 | C48: 1144 | D48: 1142 | E48: 1142 | F48: 1142
A49: Retained Earnings | B49: 40365 | C49: 35453 | D49: 32517 | E49: 30883 | F49: 29931
A50: Comprehensive Income & Other | B50: -749 | C50: 2976 | D50: 1618 | E50: 3574 | F50: 2121
A51: Total Common Equity | B51: 40792 | C51: 39573 | D51: 35277 | E51: 35599 | F51: 33194
A52: Minority Interest | B52: 1289 | C52: 1350 | D52: 1368 | E52: 1284 | F52: 1143
A53: Shareholders' Equity | B53: 42081 | C53: 40923 | D53: 36645 | E53: 36883 | F53: 34337
...

Sheet Cash Flow
A1: BASF — Cash Flow Analysis (FY2021–FY2025)
A2: Fiscal Year | B2: FY 2021 | C2: FY 2022 | D2: FY 2023 | E2: FY 2024 | F2: FY 2025
A3: Net Income | B3: ='Income Statement'!B27 -> 5523 | C3: ='Income Statement'!C27 -> -627 | D3: ='Income Statement'!D27 -> 225 | E3: ='Income Statement'!E27 -> 1298 | F3: ='Income Statement'!F27 -> 1619
A4: Depreciation & Amortization | B4: 3518 | C4: 3800 | D4: 3769 | E4: 3647 | F4: 3580
A5: Other Amortization | B5: 25 | C5: 27 | D5: 29 | E5: 0 | F5: 0
A6: Loss (Gain) From Sale of Assets | B6: -611 | C6: -1 | D6: -103 | E6: -57 | F6: -842
A7: Asset Writedown & Restructuring Costs | B7: 144 | C7: 373 | D7: 1143 | E7: 753 | F7: 404
A8: Loss (Gain) on Equity Investments | B8: 0 | C8: 4499 | D8: 544 | E8: -212 | F8: 276
A9: Other Operating Activities | B9: -1 | C9: 1688 | D9: 5 | E9: 398 | F9: -230
A10: Change in Accounts Receivable | B10: -1272 | C10: 219 | D10: 1443 | E10: 42 | F10: 530
A11: Change in Inventory | B11: -3304 | C11: -1991 | D11: 1896 | E11: 222 | F11: 263
A12: Change in Accounts Payable | B12: 0 | C12: 451 | D12: -1544 | E12: 96 | F12: -736
A13: Change in Other Net Operating Assets | B13: 3223 | C13: -729 | D13: 704 | E13: 511 | F13: 564
A14: Operating Cash Flow | B14: 7245 | C14: 7709 | D14: 8111 | E14: 6946 | F14: 5610
A15: Operating Cash Flow Growth | B15: 0.3384 | C15: 0.064 | D15: 0.0521 | E15: -0.1436 | F15: -0.1923
A17: Investing Activities
A18: Fiscal Year | B18: FY 2021 | C18: FY 2022 | D18: FY 2023 | E18: FY 2024 | F18: FY 2025
A19: Capital Expenditures | B19: -3532 | C19: -4375 | D19: -5395 | E19: -6198 | F19: -4267
A20: Cash Acquisitions | B20: -600 | C20: -13 | D20: -5 | E20: -202 | F20: -1
A21: Divestitures | B21: 1030 | C21: 691 | D21: 32 | E21: 75 | F21: 871
A22: Investment in Securities | B22: -994 | C22: -1273 | D22: -1063 | E22: 436 | F22: -1121
A23: Other Investing Activities | B23: 1474 | C23: 1192 | D23: 1440 | E23: 808 | F23: 1310
A24: Investing Cash Flow | B24: -2622 | C24: -3778 | D24: -4991 | E24: -5081 | F24: -3208
A26: Financing Activities
A27: Fiscal Year | B27: FY 2021 | C27: FY 2022 | D27: FY 2023 | E27: FY 2024 | F27: FY 2025
A28: Long-Term Debt Issued | B28: 7627 | C28: 10896 | D28: 9503 | E28: 6362 | F28: 6394
A29: Long-Term Debt Repaid | B29: -10772 | C29: -10330 | D29: -9244 | E29: -4579 | F29: -6369
A30: Net Debt Issued (Repaid) | B30: -3145 | C30: 566 | D30: 259 | E30: 1783 | F30: 25
A31: Repurchase of Common Stock | B31: 0 | C31: -1331 | D31: -70 | E31: -46 | F31: -355
A32: Common Dividends Paid | B32: -3031 | C32: -3072 | D32: -3034 | E32: -3035 | F32: -2086
A33: Other Financing Activities | B33: -281 | C33: -176 | D33: -60 | E33: -249 | F33: 0
A34: Financing Cash Flow | B34: -6457 | C34: -4013 | D34: -2905 | E34: -1547 | F34: -2416
A37: Fiscal Year | B37: FY 2021 | C37: FY 2022 | D37: FY 2023 | E37: FY 2024 | F37: FY 2025
A38: Foreign Exchange Rate Adjustments | B38: 131 | C38: -25 | D38: -106 | E38: -21 | F38: -88
A39: Miscellaneous Cash Flow Adjustments | B39: -8 | C39: -1 | D39: 0 | E39: 0 | F39: -1
A40: Net Cash Flow | B40: -1711 | C40: -108 | D40: 109 | E40: 297 | F40: -103

Sheet Financial Performance and Risk
A1: BASF Financial Performance & Risk Analysis (FY2021–FY2025)
A3: Key Financial Analysis Inputs | B3: FY2021 | C3: FY2022 | D3: FY2023 | E3: FY2024 | F3: FY2025
A4: Total Assets | B4: ='Balance Sheet'!B22 -> 87383 | C4: ='Balance Sheet'!C22 -> 84472 | D4: ='Balance Sheet'!D22 -> 77395 | E4: ='Balance Sheet'!E22 -> 80415 | F4: ='Balance Sheet'!F22 -> 76174
A5: Average Total Assets | C5: =AVERAGE('Balance Sheet'!B22,'Balance Sheet'!C22) -> 85927.5 | D5: =AVERAGE('Balance Sheet'!C22,'Balance Sheet'!D22) -> 80933.5 | E5: =AVERAGE('Balance Sheet'!D22,'Balance Sheet'!E22) -> 78905 | F5: =AVERAGE('Balance Sheet'!E22,'Balance Sheet'!F22) -> 78294.5
A6: Shareholders' Equity | B6: ='Balance Sheet'!B53 -> 42081 | C6: ='Balance Sheet'!C53 -> 40923 | D6: ='Balance Sheet'!D53 -> 36645 | E6: ='Balance Sheet'!E53 -> 36883 | F6: ='Balance Sheet'!F53 -> 34337
A7: Average Shareholder Equity | C7: =AVERAGE('Balance Sheet'!B53,'Balance Sheet'!C53) -> 41502 | D7: =AVERAGE('Balance Sheet'!C53,'Balance Sheet'!D53) -> 38784 | E7: =AVERAGE('Balance Sheet'!D53,'Balance Sheet'!E53) -> 36764 | F7: =AVERAGE('Balance Sheet'!E53,'Balance Sheet'!F53) -> 35610
A8: Average Accounts Receivable | C8: =AVERAGE('Balance Sheet'!B8,'Balance Sheet'!C8) -> 12001.5 | D8: =AVERAGE('Balance Sheet'!C8,'Balance Sheet'!D8) -> 11237 | E8: =AVERAGE('Balance Sheet'!D8,'Balance Sheet'!E8) -> 10405 | F8: =AVERAGE('Balance Sheet'!E8,'Balance Sheet'!F8) -> 9360
A9: Average Inventory | C9: =AVERAGE('Balance Sheet'!B11,'Balance Sheet'!C11) -> 14948 | D9: =AVERAGE('Balance Sheet'!C11,'Balance Sheet'!D11) -> 14952 | E9: =AVERAGE('Balance Sheet'!D11,'Balance Sheet'!E11) -> 13778.5 | F9: =AVERAGE('Balance Sheet'!E11,'Balance Sheet'!F11) -> 12924.5
A10: Average Accounts Payable | C10: =AVERAGE('Balance Sheet'!B28,'Balance Sheet'!C28) -> 8130 | D10: =AVERAGE('Balance Sheet'!C28,'Balance Sheet'!D28) -> 7587.5 | E10: =AVERAGE('Balance Sheet'!D28,'Balance Sheet'!E28) -> 6832 | F10: =AVERAGE('Balance Sheet'!E28,'Balance Sheet'!F28) -> 6203.5
A11: Total Debt | B11: ='Balance Sheet'!B44 -> 17724 | C11: ='Balance Sheet'!C44 -> 19461 | D11: ='Balance Sheet'!D44 -> 19698 | E11: ='Balance Sheet'!E44 -> 22332 | F11: ='Balance Sheet'!F44 -> 21655
A12: EBITDA | B12: ='Income Statement'!B10+'Cash Flow'!B4 -> 10985 | C12: ='Income Statement'!C10+'Cash Flow'!C4 -> 10656 | D12: ='Income Statement'!D10+'Cash Flow'!D4 -> 6610 | E12: ='Income Statement'!E10+'Cash Flow'!E4 -> 6131 | F12: ='Income Statement'!F10+'Cash Flow'!F4 -> 6053
A14: Working Capital Analysis
A15: Metric | B15: FY2021 | C15: FY2022 | D15: FY2023 | E15: FY2024 | F15: FY2025
A16: Working Capital | B16: ='Balance Sheet'!B14-'Balance Sheet'!B36 -> 14970 | C16: ='Balance Sheet'!C14-'Balance Sheet'!C36 -> 16982 | D16: ='Balance Sheet'!D14-'Balance Sheet'!D36 -> 15601 | E16: ='Balance Sheet'!E14-'Balance Sheet'!E36 -> 14193 | F16: ='Balance Sheet'!F14-'Balance Sheet'!F36 -> 15273
A17: Changes in Working Capital | C17: =C16-B16 -> 2012 | D17: =D16-C16 -> -1381 | E17: =E16-D16 -> -1408 | F17: =F16-E16 -> 1080
A18: The analysis shows that BASF maintained positive working capital throughout FY2021–FY2025, indicating that current assets remained above current liabilities. Working capital increased to €16.982 billion in FY2022 before declining to €14.193 billion in FY2024, then recovering to €15.273 billion in FY2025. Overall, the FY2025 improvement is positive, but management should continue focusing on efficient working-capital management and avoiding excessive cash being tied up in operations.
A20: Liquidity Analysis
A21: Metric | B21: FY2021 | C21: FY2022 | D21: FY2023 | E21: FY2024 | F21: FY2025
A22: Current Ratio | B22: ='Balance Sheet'!B14/'Balance Sheet'!B36 -> 1.7454808 | C22: ='Balance Sheet'!C14/'Balance Sheet'!C36 -> 1.8308219 | D22: ='Balance Sheet'!D14/'Balance Sheet'!D36 -> 1.9829878 | E22: ='Balance Sheet'!E14/'Balance Sheet'!E36 -> 1.8329714 | F22: ='Balance Sheet'!F14/'Balance Sheet'!F36 -> 1.9306563
A23: Quick Ratio | B23: =('Balance Sheet'!B14-'Balance Sheet'!B11)/'Balance Sheet'!B36 -> 1.0548777 | C23: =('Balance Sheet'!C14-'Balance Sheet'!C11)/'Balance Sheet'!C36 -> 1.0466732 | D23: =('Balance Sheet'!D14-'Balance Sheet'!D11)/'Balance Sheet'!D36 -> 1.1086888 | E23: =('Balance Sheet'!E14-'Balance Sheet'!E11)/'Balance Sheet'!E36 -> 1.0300487 | F23: =('Balance Sheet'!F14-'Balance Sheet'!F11)/'Balance Sheet'!F36 -> 1.1892024
A24: Cash Ratio | B24: ='Balance Sheet'!B3/'Balance Sheet'!B36 -> 0.13067078 | C24: ='Balance Sheet'!C3/'Balance Sheet'!C36 -> 0.12309198 | D24: ='Balance Sheet'!D3/'Balance Sheet'!D36 -> 0.165333 | E24: ='Balance Sheet'!E3/'Balance Sheet'!E36 -> 0.17101943 | F24: ='Balance Sheet'!F3/'Balance Sheet'!F36 -> 0.16269575
A25: The liquidity analysis shows that BASF maintained a solid short-term liquidity position throughout FY2021–FY2025. The Current Ratio remained above 1.7x and reached 1.93x in FY2025, while the Quick Ratio improved to 1.19x, indicating stronger coverage of current liabilities without relying on inventory. The Cash Ratio remained relatively low at around 0.12–0.17x, suggesting that BASF continues to rely on other current assets and operating cash flows to meet short-term obligations. Overall, liquidity appears adequate and improved in FY2025.
A27: Profitability Analysis
A28: Metric | B28: FY2021 | C28: FY2022 | D28: FY2023 | E28: FY2024 | F28: FY2025
A29: Gross Profit Margin | B29: ='Income Statement'!B5/'Income Statement'!B2 -> 0.24818698 | C29: ='Income Statement'!C5/'Income Statement'!C2 -> 0.23623851 | D29: ='Income Statement'!D5/'Income Statement'!D2 -> 0.23796116 | E29: ='Income Statement'!E5/'Income Statement'!E2 -> 0.24265998 | F29: ='Income Statement'!F5/'Income Statement'!F2 -> 0.23685402
A30: Operating Profit Margin | B30: ='Income Statement'!B10/'Income Statement'!B2 -> 0.095002417 | C30: ='Income Statement'!C10/'Income Statement'!C2 -> 0.07850951 | D30: ='Income Statement'!D10/'Income Statement'!D2 -> 0.041232475 | E30: ='Income Statement'!E10/'Income Statement'!E2 -> 0.040427056 | F30: ='Income Statement'!F10/'Income Statement'!F2 -> 0.041453643
A31: Net Profit Margin | B31: ='Income Statement'!B27/'Income Statement'!B2 -> 0.070268964 | C31: ='Income Statement'!C27/'Income Statement'!C2 -> -0.00717991 | D31: ='Income Statement'!D27/'Income Statement'!D2 -> 0.0032655075 | E31: ='Income Statement'!E27/'Income Statement'!E2 -> 0.021124927 | F31: ='Income Statement'!F27/'Income Statement'!F2 -> 0.027138475
A32: ROA | C32: ='Income Statement'!C27/C5 -> -0.0072968491 | D32: ='Income Statement'!D27/D5 -> 0.0027800602 | E32: ='Income Statement'!E27/E5 -> 0.016450162 | F32: ='Income Statement'!F27/F5 -> 0.020678336
A33: ROE | C33: ='Income Statement'!C27/C7 -> -0.015107706 | D33: ='Income Statement'!D27/D7 -> 0.0058013614 | E33: ='Income Statement'!E27/E7 -> 0.035306278 | F33: ='Income Statement'!F27/F7 -> 0.045464757
A34: Profitability analysis shows a significant decline in operating profitability after FY2021, with operating profit margin falling from 9.50% to about 4.15% in FY2025. Gross profit margin remained relatively stable at around 24%. Net profit margin recovered from the FY2022 loss to 2.71% in FY2025, while ROA and ROE improved.
A36: Efficiency / Activity Analysis
A37: Metric | B37: FY2021 | C37: FY2022 | D37: FY2023 | E37: FY2024 | F37: FY2025
A38: Accounts Receivable Turnover | C38: ='Income Statement'!C2/C8 -> 7.2763405 | D38: ='Income Statement'!D2/D8 -> 6.1317078 | E38: ='Income Statement'!E2/E8 -> 5.9052379 | F38: ='Income Statement'!F2/F8 -> 6.3736111
A39: Total Asset Turnover | C39: ='Income Statement'!C2/C5 -> 1.016287 | D39: ='Income Statement'!D2/D5 -> 0.85134092 | E39: ='Income Statement'!E2/E5 -> 0.77870857 | F39: ='Income Statement'!F2/F5 -> 0.76195646
A40: Inventory Turnover | C40: ='Income Statement'!C4/C9 -> 4.4619347 | D40: ='Income Statement'!D4/D9 -> 3.5116372 | E40: ='Income Statement'!E4/E9 -> 3.3772907 | F40: ='Income Statement'!F4/F9 -> 3.5225347
A41: Days Sales Outstanding (DSO) | C41: =C8/'Income Statement'!C2*365 -> 50.162579 | D41: =D8/'Income Statement'!D2*365 -> 59.526647 | E41: =E8/'Income Statement'!E2*365 -> 61.809534 | F41: =F8/'Income Statement'!F2*365 -> 57.267379
A42: Days Inventory Outstanding (DIO) | C42: =C9/'Income Statement'!C4*365 -> 81.80308 | D42: =D9/'Income Statement'!D4*365 -> 103.94012 | E42: =E9/'Income Statement'!E4*365 -> 108.07479 | F42: =F9/'Income Statement'!F4*365 -> 103.61857
A43: Days Payable Outstanding (DPO) | C43: =C10/'Income Statement'!C4*365 -> 44.491506 | D43: =D10/'Income Statement'!D4*365 -> 52.745162 | E43: =E10/'Income Statement'!E4*365 -> 53.588344 | F43: =F10/'Income Statement'!F4*365 -> 49.734828
A44: The efficiency analysis shows that BASF’s operational efficiency weakened compared with FY2022. Accounts receivable turnover improved slightly in FY2025 and DSO declined to 89.1 days, while inventory turnover also improved slightly and DIO fell to 158.5 days. However, Total Asset Turnover continued to decline from 1.02x to 0.76x, indicating weaker asset utilization. Overall, FY2025 shows some improvement in working-capital efficiency, but asset utilization and cash conversion remain areas for improvement.
A45: Cash Flow Analysis
...
